<?xml version="1.0" ?>
<sdf version="1.8">

<model name="f1_tenth" canonical_link="base">
    <static>false</static>
    <link name="base">
      <inertial>
        <pose>0 0 0 0 0 0</pose>
            <mass>3.5</mass>
            <inertia>
              <ixx>0.021262</ixx>
              <iyy>0.072917</iyy>
              <izz>0.094179</izz>
            </inertia>
          </inertial>
      <visual name="baseVisual">
        <pose>.1371 0 -.0115 -0.018 0 1.5707</pose>
        <geometry>
          <mesh>
            <uri>package://f1_tenth_description/models/f1_tenth/meshes/base.dae</uri>
          </mesh>
        </geometry>
      </visual>
      <visual name="topVisual">
        <pose>.1371 0 -.0115 -0.018 0 1.5707</pose>
        <geometry>
          <mesh>
            <uri>package://f1_tenth_description/models/f1_tenth/meshes/top.dae</uri>
          </mesh>
        </geometry>
      </visual>
      <collision name="baseCollision">
        <pose>0 0 .06 0 0 0</pose>
        <geometry>
          <box>
            <size>.3 .09 .12</size>
          </box>
        </geometry>
      </collision>

      <visual name='zedVisual'>
        <pose>0.075 0 0.091 1.5707 0 1.5707</pose>
        <geometry>
          <mesh>
            <scale>0.007 0.007 0.007</scale>
            <uri>package://f1_tenth_description/models/f1_tenth/meshes/zed.dae</uri>
          </mesh>
        </geometry>
      </visual>

      <visual name='hokuyoVisual'>
        <pose>0.085 0 0.07 0 0 1.5707</pose>
        <geometry>
          <mesh>
            <scale>0.001 0.001 0.001</scale>
            <uri>package://f1_tenth_description/models/f1_tenth/meshes/hokuyo.dae</uri>
          </mesh>
        </geometry>
      </visual>

      <visual name='vescVisual'>
        <pose>-0.09 -0.025 0.0475 0 0 1.5707</pose>
        <geometry>
          <mesh>
            <scale>0.7 0.7 0.7</scale>
            <uri>package://f1_tenth_description/models/f1_tenth/meshes/vesc6.dae</uri>
          </mesh>
        </geometry>
      </visual>

      <visual name='orinNanoVisual'>
        <pose>-0.025 -0.03 0.06 1.5707 3.14 -1.5707</pose>
        <geometry>
          <mesh>
            <scale>0.008 0.008 0.008</scale>
            <uri>package://f1_tenth_description/models/f1_tenth/meshes/orin.dae</uri>
          </mesh>
        </geometry>
      </visual>

      <sensor name='hokuyo' type='gpu_lidar'>
        <pose relative_to="lidar_frame">0 0 0.03 0 0 0</pose>
        <topic>lidar</topic>
        <update_rate>15</update_rate>
        <ray>
          <scan>
            <horizontal>
              <samples>1080</samples>
              <resolution>1</resolution>
              <min_angle>-2.3562</min_angle>
              <max_angle>2.3562</max_angle>
            </horizontal>
          </scan>
          <range>
            <min>0.06</min>
            <max>10.0</max>
            <resolution>0.004</resolution>
          </range>
        </ray>
        <always_on>1</always_on>
        <visualize>1</visualize>
      </sensor>

      <sensor name='zed' type='camera'>
        <pose relative_to="camera_frame">0.05 -0.05 0 0 0 0</pose>
        <topic>camera</topic>
        <frame>camera_frame</frame>
        <update_rate>15</update_rate>
        <visualize>1</visualize>
        <camera name='front_camera'>
          <horizontal_fov>1.5708</horizontal_fov>
          <image>
            <width>1920</width>
            <height>1080</height>
            <format>RGB_INT8</format>
          </image>
          <clip>
            <near>0.02</near>
            <far>100</far>
          </clip>
        </camera>
      </sensor>

      <sensor name="zed_depth" type="depth_camera" >
        <pose relative_to="camera_frame">0.05 -0.05 0 0 0 0</pose>
        <topic>depth_camera</topic>
        <frame>camera_frame</frame>
        <update_rate>15</update_rate>
        <visualize>1</visualize>
        <camera name="front_depth_camera">
          <horizontal_fov>1.5708</horizontal_fov>
          <image>
            <width>1280</width>
            <height>720</height>
            <format>RGB_INT8</format>
          </image>
          <clip>
            <near>0.5</near>
            <far>25.0</far>
          </clip>
        </camera>
      </sensor>

    </link>

    <link name="frontRightWheel">
      <pose relative_to="frontRightWheelJoint">0 0 0 0 0 0</pose>
      <inertial>
        <mass>.05</mass>
        <inertia>
          <ixx>0.00003331</ixx>
          <ixy>0</ixy>
          <ixz>0</ixz>
          <iyy>0.0000204</iyy>
          <iyz>0</iyz>
          <izz>0.0000204</izz>
        </inertia>
      </inertial>
      <gravity>true</gravity>
      <velocity_decay/>
      <visual name="frontRightWheelVisual">
        <pose>0 0 0 0 0 0</pose>
        <geometry>
          <mesh>
            <uri>package://f1_tenth_description/models/f1_tenth/meshes/wheel.dae</uri>
          </mesh>
        </geometry>
      </visual>
      <collision name="frontRightWheelCollision">
        <pose>0 .015 0 -1.5707 0 0</pose>
        <geometry>
          <cylinder>
            <length>0.03</length>
            <radius>0.0365</radius>
          </cylinder>
        </geometry>
        <surface>
          <friction>
            <ode>
              <mu>0.5</mu>
              <mu2>1.0</mu2>
              <fdir1>0 0 1</fdir1>
            </ode>
          </friction>
        </surface>
      </collision>
    </link>
    <link name="frontRightWheelSteering">
      <pose relative_to="frontRightWheelSteeringJoint">0 0 0 0 0 0</pose>
      <inertial>
        <mass>0.005</mass>
        <inertia>
          <ixx>0.0000018</ixx>
          <iyy>0.0000018</iyy>
          <izz>0.0000018</izz>
        </inertia>
      </inertial>
    </link>
    <link name="frontLeftWheel">
      <pose relative_to="frontLeftWheelJoint">0 0 0 0 0 0</pose>
      <inertial>
        <mass>.05</mass>
        <inertia>
          <ixx>0.00003331</ixx>
          <ixy>0</ixy>
          <ixz>0</ixz>
          <iyy>0.0000204</iyy>
          <iyz>0</iyz>
          <izz>0.0000204</izz>
        </inertia>
      </inertial>
      <gravity>true</gravity>
      <velocity_decay/>
      <visual name="frontLeftWheelVisual">
        <pose>0 0 0 0 0 3.14159</pose>
        <geometry>
          <mesh>
            <uri>package://f1_tenth_description/models/f1_tenth/meshes/wheel.dae</uri>
          </mesh>
        </geometry>
      </visual>
      <collision name="frontLeftWheelCollision">
        <pose>0 -.015 0 -1.5707 0 0</pose>
        <geometry>
          <cylinder>
            <length>0.03</length>
            <radius>0.0365</radius>
          </cylinder>
        </geometry>
        <surface>
          <friction>
            <ode>
              <mu>0.5</mu>
              <mu2>1.0</mu2>
              <fdir1>0 0 1</fdir1>
            </ode>
          </friction>
        </surface>
      </collision>
    </link>
    <link name="frontLeftWheelSteering">
      <pose relative_to="frontLeftWheelSteeringJoint">0 0 0 0 0 0</pose>
      <inertial>
        <mass>0.005</mass>
        <inertia>
          <ixx>0.0000018</ixx>
          <iyy>0.0000018</iyy>
          <izz>0.0000018</izz>
        </inertia>
      </inertial>
    </link>
    <link name="rearRightWheel">
      <pose relative_to="rearRightWheelJoint">0 0 0 0 0 0</pose>
      <inertial>
        <mass>.05</mass>
        <inertia>
          <ixx>0.00003331</ixx>
          <ixy>0</ixy>
          <ixz>0</ixz>
          <iyy>0.0000204</iyy>
          <iyz>0</iyz>
          <izz>0.0000204</izz>
        </inertia>
      </inertial>
      <gravity>true</gravity>
      <velocity_decay/>
      <visual name="rearRightWheelVisual">
        <pose>0 0 0 0 0 0</pose>
        <geometry>
          <mesh>
            <uri>package://f1_tenth_description/models/f1_tenth/meshes/wheel.dae</uri>
          </mesh>
        </geometry>
      </visual>
      <collision name="rearRightWheelCollision">
        <pose>0 .015 0 -1.5707 0 0</pose>
        <geometry>
          <cylinder>
            <length>0.03</length>
            <radius>0.0365</radius>
          </cylinder>
        </geometry>
        <surface>
          <friction>
            <ode>
              <mu>0.5</mu>
              <mu2>1.0</mu2>
              <fdir1>0 0 1</fdir1>
            </ode>
          </friction>
        </surface>
      </collision>
    </link>
    <link name="rearLeftWheel">
      <pose relative_to="rearLeftWheelJoint">0 0 0 0 0 0</pose>
      <inertial>
        <mass>.05</mass>
        <inertia>
          <ixx>0.00003331</ixx>
          <ixy>0</ixy>
          <ixz>0</ixz>
          <iyy>0.0000204</iyy>
          <iyz>0</iyz>
          <izz>0.0000204</izz>
        </inertia>
      </inertial>
      <gravity>true</gravity>
      <velocity_decay/>
      <visual name="rearLeftWheelVisual">
        <pose>0 0 0 0 0 3.14159</pose>
        <geometry>
          <mesh>
            <uri>package://f1_tenth_description/models/f1_tenth/meshes/wheel.dae</uri>
          </mesh>
        </geometry>
      </visual>
      <collision name="rearLeftWheelCollision">
        <pose>0 -.015 0 -1.5707 0 0</pose>
        <geometry>
          <cylinder>
            <length>0.03</length>
            <radius>0.0365</radius>
          </cylinder>
        </geometry>
        <surface>
          <friction>
            <ode>
              <mu>0.5</mu>
              <mu2>1.0</mu2>
              <fdir1>0 0 1</fdir1>
            </ode>
          </friction>
        </surface>
      </collision>
    </link>
    <joint name="frontRightWheelSteeringJoint" type="revolute">
      <parent>base</parent>
      <child>frontRightWheelSteering</child>
      <pose relative_to="base">.112 -.10 0 0 0 0</pose>
      <axis>
        <xyz>0 0 1</xyz>
        <limit>
          <lower>-0.6</lower>
          <upper>0.6</upper>
          <velocity>1.0</velocity>
          <effort>25</effort>
        </limit>
        <use_parent_model_frame>1</use_parent_model_frame>
      </axis>
    </joint>
    <joint name="frontRightWheelJoint" type="revolute">
      <parent>frontRightWheelSteering</parent>
      <child>frontRightWheel</child>
      <pose relative_to="frontRightWheelSteeringJoint">0 0 0 0 0 0</pose>
      <axis>
        <xyz>0 1 0</xyz>
        <limit>
          <lower>-1.79769e+308</lower>
          <upper>1.79769e+308</upper>
        </limit>
        <dynamics>
          <spring_reference>0</spring_reference>
          <spring_stiffness>0</spring_stiffness>
        </dynamics>
        <use_parent_model_frame>1</use_parent_model_frame>
      </axis>
    </joint>
    <joint name="frontLeftWheelSteeringJoint" type="revolute">
      <parent>base</parent>
      <child>frontLeftWheelSteering</child>
      <pose relative_to="base">.112 .10 0 0 0 0</pose>
      <axis>
        <xyz>0 0 1</xyz>
        <limit>
          <lower>-0.6</lower>
          <upper>0.6</upper>
          <velocity>1.0</velocity>
          <effort>25</effort>
        </limit>
        <use_parent_model_frame>1</use_parent_model_frame>
      </axis>
    </joint>
    <joint name="frontLeftWheelJoint" type="revolute">
      <parent>frontLeftWheelSteering</parent>
      <child>frontLeftWheel</child>
      <pose relative_to="frontLeftWheelSteeringJoint">0 0 0 0 0 0</pose>
      <axis>
        <xyz>0 1 0</xyz>
        <limit>
          <lower>-1.79769e+308</lower>
          <upper>1.79769e+308</upper>
        </limit>
        <dynamics>
          <spring_reference>0</spring_reference>
          <spring_stiffness>0</spring_stiffness>
        </dynamics>
        <use_parent_model_frame>1</use_parent_model_frame>
      </axis>
    </joint>
    <joint name="rearRightWheelJoint" type="revolute">
      <parent>base</parent>
      <child>rearRightWheel</child>
      <pose relative_to="base">-.1135 -.10 0 0 0 0</pose>
      <axis>
        <xyz>0 1 0</xyz>
        <limit>
          <lower>-1.79769e+308</lower>
          <upper>1.79769e+308</upper>
        </limit>
        <dynamics>
          <spring_reference>0</spring_reference>
          <spring_stiffness>0</spring_stiffness>
        </dynamics>
        <use_parent_model_frame>1</use_parent_model_frame>
      </axis>
    </joint>
    <joint name="rearLeftWheelJoint" type="revolute">
      <parent>base</parent>
      <child>rearLeftWheel</child>
      <pose relative_to="base">-.1135 .10 0 0 0 0</pose>
      <axis>
        <xyz>0 1 0</xyz>
        <limit>
          <lower>-1.79769e+308</lower>
          <upper>1.79769e+308</upper>
        </limit>
        <dynamics>
          <spring_reference>0</spring_reference>
          <spring_stiffness>0</spring_stiffness>
        </dynamics>
        <use_parent_model_frame>1</use_parent_model_frame>
      </axis>
    </joint>

    <plugin
          filename="ignition-gazebo-ackermann-steering-system"
          name="ignition::gazebo::systems::AckermannSteering">
          <left_joint>frontLeftWheelJoint</left_joint>
          <left_joint>rearLeftWheelJoint</left_joint>
          <right_joint>frontRightWheelJoint</right_joint>
          <right_joint>rearRightWheelJoint</right_joint>
          <left_steering_joint>frontLeftWheelSteeringJoint</left_steering_joint>
          <right_steering_joint>frontRightWheelSteeringJoint</right_steering_joint>
          <wheel_base>.325</wheel_base>
          <wheel_separation>.23</wheel_separation>
          <kingpin_width>.19</kingpin_width>
          <wheel_radius>0.05</wheel_radius>
          <steering_limit>0.5</steering_limit>
          <min_velocity>-100</min_velocity>
          <max_velocity>100</max_velocity>
          <min_acceleration>-5</min_acceleration>
          <max_acceleration>5</max_acceleration>
          <topic>cmd_vel</topic>
          <odom_topic>ackermann_odom</odom_topic>
    </plugin>

    <frame name='base_chassis' attached_to='base'/>
    <frame name='lidar_frame' attached_to='base_chassis'>
          <pose>0.0875 0 0.07 0 0 0</pose>
    </frame>

    <frame name='camera_frame' attached_to='base_chassis'>
          <pose>0.11 0 0.091 0 0 0</pose>
    </frame>
    
  </model>
</sdf>